Workbook

Sheet BDD
B2: DATE | C2: TOKEN | D2: MONTANT | E2: COURS (usd) | F2: QUANTITE | G2: EXCHANGE
B3: 46052 | C3: BTC | D3: 15.7 | E3: 82603.9 | F3: =BDD!$D3/BDD!$E3 -> 0.00019006367 | G3: BINANCE
B4: 46054 | C4: ETH | D4: 20.44 | E4: 2376.41 | F4: =BDD!$D4/BDD!$E4 -> 0.0086012094 | G4: BINANCE
B5: 46054 | C5: SOL | D5: 15.7003 | E5: 101.95 | F5: =BDD!$D5/BDD!$E5 -> 0.154 | G5: BINANCE
B6: 46052 | C6: BNB | D6: 15.65 | E6: 851.9 | F6: =BDD!$D6/BDD!$E6 -> 0.018370701 | G6: BINANCE
B7: 46165 | C7: ZEC | D7: 10 | E7: 587.71 | F7: =BDD!$D7/BDD!$E7 -> 0.017015195 | G7: BINANCE
B8: 46060 | C8: XRP | D8: 10.36 | E8: 1.4187 | F8: =BDD!$D8/BDD!$E8 -> 7.30246 | G8: BINANCE
B9: 46061 | C9: DOGE | D9: 7.84 | E9: 0.09679 | F9: =BDD!$D9/BDD!$E9 -> 81.000103 | G9: BINANCE
B10: 46132 | C10: ZEN | D10: 10.245 | E10: 6.098 | F10: =BDD!$D10/BDD!$E10 -> 1.680059 | G10: BINANCE
B11: 46102 | C11: SUI | D11: 7.8 | E11: 0.9346 | F11: =BDD!$D11/BDD!$E11 -> 8.3458164 | G11: BINANCE
B12: 46106 | C12: TAO | D12: 12.212 | E12: 344 | F12: =BDD!$D12/BDD!$E12 -> 0.0355 | G12: BINANCE
B13: 46122 | C13: TAO | D13: 10.454 | E13: 292 | F13: =BDD!$D13/BDD!$E13 -> 0.03580137
B14: 46068 | C14: ADA | D14: 9.8 | E14: 0.2968 | F14: =BDD!$D14/BDD!$E14 -> 33.018868 | G14: BINANCE
B15: 46097 | C15: LINK | D15: 12.15 | E15: 9.72 | F15: =BDD!$D15/BDD!$E15 -> 1.25 | G15: BINANCE
B16: 46101 | C16: AVAX | D16: 5.31 | E16: 9.48 | F16: =BDD!$D16/BDD!$E16 -> 0.56012658 | G16: BINANCE
C17: XPL | F17: =BDD!$D17/BDD!$E17 -> #DIV/0! | G17: BINANCE
B18: 46122 | C18: VIRTUAL | D18: 8.2475 | E18: 0.6816 | F18: =BDD!$D18/BDD!$E18 -> 12.100205 | G18: BINANCE
C19: PUMP | F19: =BDD!$D19/BDD!$E19 -> #DIV/0! | G19: BINANCE
B20: 46143 | C20: ENA | D20: 7.6022 | E20: 0.1036 | F20: =BDD!$D20/BDD!$E20 -> 73.380309 | G20: BINANCE
B21: 46102 | C21: WLD | D21: 7.946 | E21: 0.3204 | F21: =BDD!$D21/BDD!$E21 -> 24.80025 | G21: BINANCE
B22: 46106 | C22: NEAR | D22: 5.7 | E22: 1.294 | F22: =BDD!$D22/BDD!$E22 -> 4.4049459 | G22: BINANCE
B23: 46155 | C23: AAVE | D23: 8.91 | E23: 98.98 | F23: =BDD!$D23/BDD!$E23 -> 0.090018185 | G23: BINANCE
C24: ARB | F24: =BDD!$D24/BDD!$E24 -> #DIV/0! | G24: BINANCE
C25: PENGU | F25: =BDD!$D25/BDD!$E25 -> #DIV/0! | G25: BINANCE
C26: WLFI | F26: =BDD!$D26/BDD!$E26 -> #DIV/0! | G26: BINANCE
C27: ONDO | F27: =BDD!$D27/BDD!$E27 -> #DIV/0! | G27: BINANCE
B28: 46059 | C28: ATOM | D28: 10.534 | E28: 1.813 | F28: =BDD!$D28/BDD!$E28 -> 5.8102592 | G28: BINANCE
C29: AR | F29: =BDD!$D29/BDD!$E29 -> #DIV/0! | G29: BINANCE
C30: TIA | F30: =BDD!$D30/BDD!$E30 -> #DIV/0! | G30: BINANCE
B31: 46111 | C31: INJ | D31: 8.8 | E31: 5.839 | F31: =BDD!$D31/BDD!$E31 -> 1.5071074 | G31: BINANCE
B32: 46111 | C32: FET | D32: 8.6135 | E32: 0.2386 | F32: =BDD!$D32/BDD!$E32 -> 36.100168 | G32: BINANCE
B33: 46152 | C33: RENDER | D33: 8.25 | E33: 1.987 | F33: =BDD!$D33/BDD!$E33 -> 4.1519879 | G33: BINANCE
C34: NMR | F34: =BDD!$D34/BDD!$E34 -> #DIV/0! | G34: BINANCE
C35: PYTH | F35: =BDD!$D35/BDD!$E35 -> #DIV/0! | G35: BINANCE
B36: 46122 | C36: W | D36: 12.0125 | E36: 0.0129 | F36: =BDD!$D36/BDD!$E36 -> 931.20155 | G36: BINANCE
B37: 46163 | C37: GRT | D37: 10.2 | E37: 0.02575 | F37: =BDD!$D37/BDD!$E37 -> 396.1165 | G37: BINANCE
C38: QNT | F38: =BDD!$D38/BDD!$E38 -> #DIV/0! | G38: BINANCE
C39: AXL | F39: =BDD!$D39/BDD!$E39 -> #DIV/0! | G39: BINANCE
C40: ILV | F40: =BDD!$D40/BDD!$E40 -> #DIV/0! | G40: BINANCE
C41: QTUM | F41: =BDD!$D41/BDD!$E41 -> #DIV/0! | G41: BINANCE
...

Sheet T.BORD
C2: INVESTISSEMENT | F2: VALEUR PF NR | I2: RENTABILITE
C3: =SUM(C6:C57) -> 292.18561 | F3: =SUM(G6:G55) -> 275.58856 | I3: =(F3-C3)/C3 -> -0.056803091
B5: TOKEN | C5: MONTANT INVESTI | D5: QUANTITE ACHETEE | E5: PRU | F5: COURS ACTUEL | G5: M. NON REALISES | H5: P/L | I5: RENTABILITE
B6: {=_xlfn.UNIQUE(Tableau2[TOKEN])} -> BTC | C6: =SUMIF(Tableau2[TOKEN],T.BORD!B6,Tableau2[MONTANT]) -> 15.7 | D6: =SUMIF(Tableau2[TOKEN],T.BORD!B6,Tableau2[QUANTITE]) -> 0.00019006367 | E6: =C6/D6 -> 82603.9 | F6: ='pricemulti_fsyms=BTC,ETH,SO (2)'!B2 -> 73879.74 | G6: =F6*D6 -> 14.041854 | H6: =G6-C6 -> -1.6581458 | I6: =(G6-C6)/C6 -> -0.10561438
B7: ETH | C7: =SUMIF(Tableau2[TOKEN],T.BORD!B7,Tableau2[MONTANT]) -> 20.44 | D7: =SUMIF(Tableau2[TOKEN],T.BORD!B7,Tableau2[QUANTITE]) -> 0.0086012094 | E7: =C7/D7 -> 2376.41 | F7: ='pricemulti_fsyms=BTC,ETH,SO (2)'!B3 -> 2012.39 | G7: =F7*D7 -> 17.308988 | H7: =G7-C7 -> -3.1310122 | I7: =(G7-C7)/C7 -> -0.15318064
B8: SOL | C8: =SUMIF(Tableau2[TOKEN],T.BORD!B8,Tableau2[MONTANT]) -> 15.7003 | D8: =SUMIF(Tableau2[TOKEN],T.BORD!B8,Tableau2[QUANTITE]) -> 0.154 | E8: =C8/D8 -> 101.95 | F8: ='pricemulti_fsyms=BTC,ETH,SO (2)'!B4 -> 82.5 | G8: =F8*D8 -> 12.705 | H8: =G8-C8 -> -2.9953 | I8: =(G8-C8)/C8 -> -0.19077979
B9: BNB | C9: =SUMIF(Tableau2[TOKEN],T.BORD!B9,Tableau2[MONTANT]) -> 15.65 | D9: =SUMIF(Tableau2[TOKEN],T.BORD!B9,Tableau2[QUANTITE]) -> 0.018370701 | E9: =C9/D9 -> 851.9 | F9: ='pricemulti_fsyms=BTC,ETH,SO (2)'!B5 -> 709.73 | G9: =F9*D9 -> 13.038237 | H9: =G9-C9 -> -2.6117625 | I9: =(G9-C9)/C9 -> -0.16688578
B10: ZEC | C10: =SUMIF(Tableau2[TOKEN],T.BORD!B10,Tableau2[MONTANT]) -> 10 | D10: =SUMIF(Tableau2[TOKEN],T.BORD!B10,Tableau2[QUANTITE]) -> 0.017015195 | E10: =C10/D10 -> 587.71 | F10: ='pricemulti_fsyms=BTC,ETH,SO (2)'!B6 -> 564.93 | G10: =F10*D10 -> 9.6123939 | H10: =G10-C10 -> -0.38760613 | I10: =(G10-C10)/C10 -> -0.038760613
B11: XRP | C11: =SUMIF(Tableau2[TOKEN],T.BORD!B11,Tableau2[MONTANT]) -> 10.36 | D11: =SUMIF(Tableau2[TOKEN],T.BORD!B11,Tableau2[QUANTITE]) -> 7.30246 | E11: =C11/D11 -> 1.4187 | F11: ='pricemulti_fsyms=BTC,ETH,SO (2)'!B7 -> 1.336 | G11: =F11*D11 -> 9.7560866 | H11: =G11-C11 -> -0.60391344 | I11: =(G11-C11)/C11 -> -0.058292803
B12: DOGE | C12: =SUMIF(Tableau2[TOKEN],T.BORD!B12,Tableau2[MONTANT]) -> 7.84 | D12: =SUMIF(Tableau2[TOKEN],T.BORD!B12,Tableau2[QUANTITE]) -> 81.000103 | E12: =C12/D12 -> 0.09679 | F12: ='pricemulti_fsyms=BTC,ETH,SO (2)'!B8 -> 0.1005 | G12: =F12*D12 -> 8.1405104 | H12: =G12-C12 -> 0.30051038 | I12: =(G12-C12)/C12 -> 0.038330406
B13: ZEN | C13: =SUMIF(Tableau2[TOKEN],T.BORD!B13,Tableau2[MONTANT]) -> 10.245 | D13: =SUMIF(Tableau2[TOKEN],T.BORD!B13,Tableau2[QUANTITE]) -> 1.680059 | E13: =C13/D13 -> 6.098 | F13: ='pricemulti_fsyms=BTC,ETH,SO (2)'!B9 -> 5.916 | G13: =F13*D13 -> 9.9392293 | H13: =G13-C13 -> -0.30577074 | I13: =(G13-C13)/C13 -> -0.029845851
B14: SUI | C14: =SUMIF(Tableau2[TOKEN],T.BORD!B14,Tableau2[MONTANT]) -> 7.8 | D14: =SUMIF(Tableau2[TOKEN],T.BORD!B14,Tableau2[QUANTITE]) -> 8.3458164 | E14: =C14/D14 -> 0.9346 | F14: ='pricemulti_fsyms=BTC,ETH,SO (2)'!B10 -> 0.8974 | G14: =F14*D14 -> 7.4895356 | H14: =G14-C14 -> -0.31046437 | I14: =(G14-C14)/C14 -> -0.039803124
B15: TAO | C15: =SUMIF(Tableau2[TOKEN],T.BORD!B15,Tableau2[MONTANT]) -> 22.666 | D15: =SUMIF(Tableau2[TOKEN],T.BORD!B15,Tableau2[QUANTITE]) -> 0.07130137 | E15: =C15/D15 -> 317.89011 | F15: ='pricemulti_fsyms=BTC,ETH,SO (2)'!B11 -> 256.69 | G15: =F15*D15 -> 18.302349 | H15: =G15-C15 -> -4.3636514 | I15: =(G15-C15)/C15 -> -0.19251969
B16: ADA | C16: =SUMIF(Tableau2[TOKEN],T.BORD!B16,Tableau2[MONTANT]) -> 9.8 | D16: =SUMIF(Tableau2[TOKEN],T.BORD!B16,Tableau2[QUANTITE]) -> 33.018868 | E16: =C16/D16 -> 0.2968 | F16: ='pricemulti_fsyms=BTC,ETH,SO (2)'!B12 -> 0.2357 | G16: =F16*D16 -> 7.7825472 | H16: =G16-C16 -> -2.0174528 | I16: =(G16-C16)/C16 -> -0.20586253
B17: LINK | C17: =SUMIF(Tableau2[TOKEN],T.BORD!B17,Tableau2[MONTANT]) -> 12.15 | D17: =SUMIF(Tableau2[TOKEN],T.BORD!B17,Tableau2[QUANTITE]) -> 1.25 | E17: =C17/D17 -> 9.72 | F17: ='pricemulti_fsyms=BTC,ETH,SO (2)'!B13 -> 9.165 | G17: =F17*D17 -> 11.45625 | H17: =G17-C17 -> -0.69375 | I17: =(G17-C17)/C17 -> -0.057098765
B18: AVAX | C18: =SUMIF(Tableau2[TOKEN],T.BORD!B18,Tableau2[MONTANT]) -> 5.31 | D18: =SUMIF(Tableau2[TOKEN],T.BORD!B18,Tableau2[QUANTITE]) -> 0.56012658 | E18: =C18/D18 -> 9.48 | F18: ='pricemulti_fsyms=BTC,ETH,SO (2)'!B14 -> 8.979 | G18: =F18*D18 -> 5.0293766 | H18: =G18-C18 -> -0.28062342 | I18: =(G18-C18)/C18 -> -0.052848101
B19: XPL | C19: =SUMIF(Tableau2[TOKEN],T.BORD!B19,Tableau2[MONTANT]) -> 0 | E19: =C19/D19 -> #DIV/0! | F19: ='pricemulti_fsyms=BTC,ETH,SO (2)'!B15 -> 0.0901 | G19: =F19*D19 -> 0 | H19: =G19-C19 -> 0 | I19: =(G19-C19)/C19 -> #DIV/0! | J19: =SUM(A19:D19) -> 0
B20: VIRTUAL | C20: =SUMIF(Tableau2[TOKEN],T.BORD!B20,Tableau2[MONTANT]) -> 8.2475 | D20: =SUMIF(Tableau2[TOKEN],T.BORD!B20,Tableau2[QUANTITE]) -> 12.100205 | E20: =C20/D20 -> 0.6816 | F20: ='pricemulti_fsyms=BTC,ETH,SO (2)'!B16 -> 0.7245 | G20: =F20*D20 -> 8.7665988 | H20: =G20-C20 -> 0.51909881 | I20: =(G20-C20)/C20 -> 0.062940141
B21: PUMP | C21: =SUMIF(Tableau2[TOKEN],T.BORD!B21,Tableau2[MONTANT]) -> 0 | E21: =C21/D21 -> #DIV/0! | F21: ='pricemulti_fsyms=BTC,ETH,SO (2)'!B17 -> 0.001801 | G21: =F21*D21 -> 0 | H21: =G21-C21 -> 0 | I21: =(G21-C21)/C21 -> #DIV/0!
B22: ENA | C22: =SUMIF(Tableau2[TOKEN],T.BORD!B22,Tableau2[MONTANT]) -> 7.6022 | D22: =SUMIF(Tableau2[TOKEN],T.BORD!B22,Tableau2[QUANTITE]) -> 73.380309 | E22: =C22/D22 -> 0.1036 | F22: ='pricemulti_fsyms=BTC,ETH,SO (2)'!B18 -> 0.08839 | G22: =F22*D22 -> 6.4860855 | H22: =G22-C22 -> -1.1161145 | I22: =(G22-C22)/C22 -> -0.14681467
B23: WLD | C23: =SUMIF(Tableau2[TOKEN],T.BORD!B23,Tableau2[MONTANT]) -> 7.946 | D23: =SUMIF(Tableau2[TOKEN],T.BORD!B23,Tableau2[QUANTITE]) -> 24.80025 | E23: =C23/D23 -> 0.3204 | F23: ='pricemulti_fsyms=BTC,ETH,SO (2)'!B19 -> 0.3493 | G23: =F23*D23 -> 8.6627272 | H23: =G23-C23 -> 0.71672722 | I23: =(G23-C23)/C23 -> 0.09019975
B24: NEAR | C24: =SUMIF(Tableau2[TOKEN],T.BORD!B24,Tableau2[MONTANT]) -> 5.7 | D24: =SUMIF(Tableau2[TOKEN],T.BORD!B24,Tableau2[QUANTITE]) -> 4.4049459 | E24: =C24/D24 -> 1.294 | F24: ='pricemulti_fsyms=BTC,ETH,SO (2)'!B20 -> 2.333 | G24: =F24*D24 -> 10.276739 | H24: =G24-C24 -> 4.5767388 | I24: =(G24-C24)/C24 -> 0.80293663
B25: AAVE | C25: =SUMIF(Tableau2[TOKEN],T.BORD!B25,Tableau2[MONTANT]) -> 8.91 | D25: =SUMIF(Tableau2[TOKEN],T.BORD!B25,Tableau2[QUANTITE]) -> 0.090018185 | E25: =C25/D25 -> 98.98 | F25: ='pricemulti_fsyms=BTC,ETH,SO (2)'!B21 -> 82.32 | G25: =F25*D25 -> 7.410297 | H25: =G25-C25 -> -1.499703 | I25: =(G25-C25)/C25 -> -0.16831683
B26: ARB | C26: =SUMIF(Tableau2[TOKEN],T.BORD!B26,Tableau2[MONTANT]) -> 0 | E26: =C26/D26 -> #DIV/0! | F26: ='pricemulti_fsyms=BTC,ETH,SO (2)'!B22 -> 0.104 | G26: =F26*D26 -> 0 | H26: =G26-C26 -> 0 | I26: =(G26-C26)/C26 -> #DIV/0!
B27: PENGU | C27: =SUMIF(Tableau2[TOKEN],T.BORD!B27,Tableau2[MONTANT]) -> 0 | E27: =C27/D27 -> #DIV/0! | F27: ='pricemulti_fsyms=BTC,ETH,SO (2)'!B23 -> 0.007946 | G27: =F27*D27 -> 0 | H27: =G27-C27 -> 0 | I27: =(G27-C27)/C27 -> #DIV/0!
B28: WLFI | C28: =SUMIF(Tableau2[TOKEN],T.BORD!B28,Tableau2[MONTANT]) -> 0 | E28: =C28/D28 -> #DIV/0! | F28: ='pricemulti_fsyms=BTC,ETH,SO (2)'!B24 -> 0.05931 | G28: =F28*D28 -> 0 | H28: =G28-C28 -> 0 | I28: =(G28-C28)/C28 -> #DIV/0!
B29: ONDO | C29: =SUMIF(Tableau2[TOKEN],T.BORD!B29,Tableau2[MONTANT]) -> 0 | E29: =C29/D29 -> #DIV/0! | F29: ='pricemulti_fsyms=BTC,ETH,SO (2)'!B25 -> 0.3637 | G29: =F29*D29 -> 0 | H29: =G29-C29 -> 0 | I29: =(G29-C29)/C29 -> #DIV/0!
B30: ATOM | C30: =SUMIF(Tableau2[TOKEN],T.BORD!B30,Tableau2[MONTANT]) -> 10.534 | D30: =SUMIF(Tableau2[TOKEN],T.BORD!B30,Tableau2[QUANTITE]) -> 5.8102592 | E30: =C30/D30 -> 1.813 | F30: ='pricemulti_fsyms=BTC,ETH,SO (2)'!B26 -> 1.951 | G30: =F30*D30 -> 11.335816 | H30: =G30-C30 -> 0.80181577 | I30: =(G30-C30)/C30 -> 0.076116933
B31: AR | C31: =SUMIF(Tableau2[TOKEN],T.BORD!B31,Tableau2[MONTANT]) -> 0 | E31: =C31/D31 -> #DIV/0! | F31: ='pricemulti_fsyms=BTC,ETH,SO (2)'!B27 -> 2.247 | G31: =F31*D31 -> 0 | H31: =G31-C31 -> 0 | I31: =(G31-C31)/C31 -> #DIV/0!
B32: TIA | C32: =SUMIF(Tableau2[TOKEN],T.BORD!B32,Tableau2[MONTANT]) -> 0 | E32: =C32/D32 -> #DIV/0! | F32: ='pricemulti_fsyms=BTC,ETH,SO (2)'!B28 -> 0.4012 | G32: =F32*D32 -> 0 | H32: =G32-C32 -> 0 | I32: =(G32-C32)/C32 -> #DIV/0!
B33: INJ | C33: =SUMIF(Tableau2[TOKEN],T.BORD!B33,Tableau2[MONTANT]) -> 8.8 | D33: =SUMIF(Tableau2[TOKEN],T.BORD!B33,Tableau2[QUANTITE]) -> 1.5071074 | E33: =C33/D33 -> 5.839 | F33: ='pricemulti_fsyms=BTC,ETH,SO (2)'!B29 -> 6.561 | G33: =F33*D33 -> 9.8881315 | H33: =G33-C33 -> 1.0881315 | I33: =(G33-C33)/C33 -> 0.12365131
B34: FET | C34: =SUMIF(Tableau2[TOKEN],T.BORD!B34,Tableau2[MONTANT]) -> 8.6135 | D34: =SUMIF(Tableau2[TOKEN],T.BORD!B34,Tableau2[QUANTITE]) -> 36.100168 | E34: =C34/D34 -> 0.2386 | F34: ='pricemulti_fsyms=BTC,ETH,SO (2)'!B30 -> 0.2684 | G34: =F34*D34 -> 9.689285 | H34: =G34-C34 -> 1.075785 | I34: =(G34-C34)/C34 -> 0.12489522
B35: RENDER | C35: =SUMIF(Tableau2[TOKEN],T.BORD!B35,Tableau2[MONTANT]) -> 8.25 | D35: =SUMIF(Tableau2[TOKEN],T.BORD!B35,Tableau2[QUANTITE]) -> 4.1519879 | E35: =C35/D35 -> 1.987 | F35: ='pricemulti_fsyms=BTC,ETH,SO (2)'!B31 -> 2.093 | G35: =F35*D35 -> 8.6901107 | H35: =G35-C35 -> 0.44011072 | I35: =(G35-C35)/C35 -> 0.053346754
B36: NMR | C36: =SUMIF(Tableau2[TOKEN],T.BORD!B36,Tableau2[MONTANT]) -> 0 | E36: =C36/D36 -> #DIV/0! | F36: ='pricemulti_fsyms=BTC,ETH,SO (2)'!B32 -> 8.65 | G36: =F36*D36 -> 0 | H36: =G36-C36 -> 0 | I36: =(G36-C36)/C36 -> #DIV/0!
B37: PYTH | C37: =SUMIF(Tableau2[TOKEN],T.BORD!B37,Tableau2[MONTANT]) -> 0 | E37: =C37/D37 -> #DIV/0! | F37: ='pricemulti_fsyms=BTC,ETH,SO (2)'!B33 -> 0.04129 | G37: =F37*D37 -> 0 | H37: =G37-C37 -> 0 | I37: =(G37-C37)/C37 -> #DIV/0!
B38: W | C38: =SUMIF(Tableau2[TOKEN],T.BORD!B38,Tableau2[MONTANT]) -> 12.0125 | D38: =SUMIF(Tableau2[TOKEN],T.BORD!B38,Tableau2[QUANTITE]) -> 931.20155 | E38: =C38/D38 -> 0.0129 | F38: ='pricemulti_fsyms=BTC,ETH,SO (2)'!B34 -> 0.01191 | G38: =F38*D38 -> 11.09061 | H38: =G38-C38 -> -0.92188953 | I38: =(G38-C38)/C38 -> -0.076744186
B39: GRT | C39: =SUMIF(Tableau2[TOKEN],T.BORD!B39,Tableau2[MONTANT]) -> 10.2 | D39: =SUMIF(Tableau2[TOKEN],T.BORD!B39,Tableau2[QUANTITE]) -> 396.1165 | E39: =C39/D39 -> 0.02575 | F39: ='pricemulti_fsyms=BTC,ETH,SO (2)'!B35 -> 0.026 | G39: =F39*D39 -> 10.299029 | H39: =G39-C39 -> 0.099029126 | I39: =(G39-C39)/C39 -> 0.0097087379
B40: QNT | C40: =SUMIF(Tableau2[TOKEN],T.BORD!B40,Tableau2[MONTANT]) -> 0 | E40: =C40/D40 -> #DIV/0! | F40: ='pricemulti_fsyms=BTC,ETH,SO (2)'!B36 -> 71.57 | G40: =F40*D40 -> 0 | H40: =G40-C40 -> 0 | I40: =(G40-C40)/C40 -> #DIV/0!
B41: AXL | C41: =SUMIF(Tableau2[TOKEN],T.BORD!B41,Tableau2[MONTANT]) -> 0 | E41: =C41/D41 -> #DIV/0! | F41: ='pricemulti_fsyms=BTC,ETH,SO (2)'!B37 -> 0.05501 | G41: =F41*D41 -> 0 | H41: =G41-C41 -> 0 | I41: =(G41-C41)/C41 -> #DIV/0!
B42: ILV | C42: =SUMIF(Tableau2[TOKEN],T.BORD!B42,Tableau2[MONTANT]) -> 0 | E42: =C42/D42 -> #DIV/0! | F42: ='pricemulti_fsyms=BTC,ETH,SO (2)'!B38 -> 4.111 | G42: =F42*D42 -> 0 | H42: =G42-C42 -> 0 | I42: =(G42-C42)/C42 -> #DIV/0!
...

Sheet pricemulti_fsyms=BTC,ETH,SO (2)
A1: Name | B1: Value.USD
A2: BTC | B2: 73879.74
A3: ETH | B3: 2012.39
A4: SOL | B4: 82.5
A5: BNB | B5: 709.73
A6: ZEC | B6: 564.93
A7: XRP | B7: 1.336
A8: DOGE | B8: 0.1005
A9: ZEN | B9: 5.916
A10: SUI | B10: 0.8974
A11: TAO | B11: 256.69
A12: ADA | B12: 0.2357
A13: LINK | B13: 9.165
... A43: RSR | B43: 0.00163

Sheet Feuil1
B2: MONTANT INVESTI
B4: 20300 | F4: 20300
B5: 5075 | F5: 5100
B6: 5075 | D6: PERTES | F6: 6100
B7: 15225 | D7: =SUM(B4:B103) -> 412770 | F7: 7050
B8: 15225 | F8: 5000
B9: 20300 | F9: 10150
B10: 21315 | D10: NOUVEAUX | F10: 5100
B11: 10660 | D11: =SUM(F4:F19) -> 79650 | F11: 3050
B12: 14750 | F12: 6600
B13: 10620 | F13: 6100
B14: 10600 | D14: TOTAL | F14: 5100
B15: 8000 | D15: =SUM(D7+D11) -> 492420
B16: 5100
B17: 12200
B18: 9700
B19: 5100
B20: 5100
B21: 5100
B22: 10100
B23: 3100
B24: 5100
B25: 11200
B26: 5100
B27: 5100
... B37: 44675
